Workbook

Sheet All
A1: Demographics | H1: IPSm | AF1: Success | CF1: Self Efficacy | DS1: TRI | DT1: TRI
BU2: Time between | BW2: Basic Training | BY2: Served as | CC2: If yes, how | CF2: Pre | CS2: Post | DE2: Procedure confidence | DQ2: File name | DS2: Adj_IPSm | DT2: IPSm | DV2: Success | DW2: Success | DX2: Critical errors
F3: Study | H3: AAE | N3: FAE | T3: LEF | Z3: UEF | AF3: AAE | AG3: FAE | AJ3: LEF | AN3: UEF | BO3: Number of | BR3: Didactic | BS3: Didactic | BT3: Evaluation | BU3: didactic and | BW3: Completion | BX3: Months Served | BY3: Operating Room | BZ3: If yes, how | CA3: Deployed | CB3: If yes, how | CC3: many combat | CD3: Cadaver lab | CF3: Succeed at any | CG3: Even when things | CH3: Determine the | CI3: Control | CJ3: Plan appropriate | CK3: Conduct surgical | CL3: When to use | CM3: Appropriate | CN3: ID specific | CO3: ID bony | CP3: Performing | CQ3: Caffeinated | CS3: Succeed at any | CT3: Even when things | CU3: Determine the | CV3: Control | CW3: Plan appropriate | CX3: Conduct surgical | CY3: When to use | CZ3: Appropriate | DA3: ID specific | DB3: ID bony | DC3: Performing | DV3: All Vascular | DW3: All Fasciotomy
A4: Name | B4: Participant ID | D4: Filename | F4: Group | H4: Anatomy | I4: Pathophysiology | J4: Management | K4: Procedural | L4: Technique | N4: Anatomy | O4: Pathophysiology | P4: Management | Q4: Procedural | R4: Technique | T4: Anatomy | U4: Pathophysiology | V4: Management | W4: Procedural | X4: Technique | Z4: Anatomy | AA4: Pathophysiology | AB4: Management | AC4: Procedural | AD4: Technique | AF4: AA | AG4: CFA | AH4: SFA | AI4: PFA | AJ4: Ant | AK4: Lat | AL4: SP | AM4: DP | AN4: V | AO4: DV | AP4: BA | AQ4: MW | AR4: CT | AS4: D | BO4: Evaluators | BP4: Sequence | BQ4: Sex | BR4: Iteration # | BS4: Date | BT4: Date | BU4: evaluation | BV4: Age | BW4: (month/yr) | BX4: as a Medic | BY4: Medic or Tech | BZ4: many months | CA4: Internationally | CB4: many times | CC4: zones | CD4: experience | CF4: endeavor | CG4: are tough | CH4: need for surgery | CI4: bleeding | CJ4: interventions | CK4: procedures | CL4: tourniquet | CM4: incision | CN4: arteries | CO4: landmarks | CP4: CPR | CQ4: beverages | CS4: endeavor | CT4: are tough | CU4: need for surgery | CV4: bleeding | CW4: interventions | CX4: procedures | CY4: tourniquet | CZ4: incision | DA4: arteries | DB4: landmarks | DC4: CPR | DE4: Cric | DF4: AAE | DG4: CAE | DH4: LEF | DI4: HC-WP | DJ4: UEF | DK4: SM | DL4: Chest tube | DM4: HF | DN4: BAE | DO4: FAE
B6: M_007 | D6: =CONCATENATE(B6,".xlsx") -> M_007.xlsx | F6: =#REF! -> #REF! | H6: =#REF! -> #REF! | I6: =#REF! -> #REF! | J6: =#REF! -> #REF! | K6: =#REF! -> #REF! | L6: =#REF! -> #REF! | N6: =#REF! -> #REF! | O6: =#REF! -> #REF! | P6: =#REF! -> #REF! | Q6: =#REF! -> #REF! | R6: =#REF! -> #REF! | T6: =#REF! -> #REF! | U6: =#REF! -> #REF! | V6: =#REF! -> #REF! | W6: =#REF! -> #REF! | X6: =#REF! -> #REF! | Z6: =#REF! -> #REF! | AA6: =#REF! -> #REF! | AB6: =#REF! -> #REF! | AC6: =#REF! -> #REF! | AD6: =#REF! -> #REF! | AF6: =#REF! -> #REF! | AG6: =#REF! -> #REF! | AH6: =#REF! -> #REF! | AI6: =#REF! -> #REF! | AJ6: =#REF! -> #REF! | AK6: =#REF! -> #REF! | AL6: =#REF! -> #REF! | AM6: =#REF! -> #REF! | ... AS6: =#REF! -> #REF!
B7: M_009 | D7: =CONCATENATE(B7,".xlsx") -> M_009.xlsx | F7: =#REF! -> #REF! | H7: =#REF! -> #REF! | I7: =#REF! -> #REF! | J7: =#REF! -> #REF! | K7: =#REF! -> #REF! | L7: =#REF! -> #REF! | N7: =#REF! -> #REF! | O7: =#REF! -> #REF! | P7: =#REF! -> #REF! | Q7: =#REF! -> #REF! | R7: =#REF! -> #REF! | T7: =#REF! -> #REF! | U7: =#REF! -> #REF! | V7: =#REF! -> #REF! | W7: =#REF! -> #REF! | X7: =#REF! -> #REF! | Z7: =#REF! -> #REF! | AA7: =#REF! -> #REF! | AB7: =#REF! -> #REF! | AC7: =#REF! -> #REF! | AD7: =#REF! -> #REF! | AF7: =#REF! -> #REF! | AG7: =#REF! -> #REF! | AH7: =#REF! -> #REF! | AI7: =#REF! -> #REF! | AJ7: =#REF! -> #REF! | AK7: =#REF! -> #REF! | AL7: =#REF! -> #REF! | AM7: =#REF! -> #REF! | ... AS7: =#REF! -> #REF!
B8: M_012 | D8: =CONCATENATE(B8,".xlsx") -> M_012.xlsx | F8: =#REF! -> #REF! | H8: =#REF! -> #REF! | I8: =#REF! -> #REF! | J8: =#REF! -> #REF! | K8: =#REF! -> #REF! | L8: =#REF! -> #REF! | N8: =#REF! -> #REF! | O8: =#REF! -> #REF! | P8: =#REF! -> #REF! | Q8: =#REF! -> #REF! | R8: =#REF! -> #REF! | T8: =#REF! -> #REF! | U8: =#REF! -> #REF! | V8: =#REF! -> #REF! | W8: =#REF! -> #REF! | X8: =#REF! -> #REF! | Z8: =#REF! -> #REF! | AA8: =#REF! -> #REF! | AB8: =#REF! -> #REF! | AC8: =#REF! -> #REF! | AD8: =#REF! -> #REF! | AF8: =#REF! -> #REF! | AG8: =#REF! -> #REF! | AH8: =#REF! -> #REF! | AI8: =#REF! -> #REF! | AJ8: =#REF! -> #REF! | AK8: =#REF! -> #REF! | AL8: =#REF! -> #REF! | AM8: =#REF! -> #REF! | ... AS8: =#REF! -> #REF!
B9: M_013 | D9: =CONCATENATE(B9,".xlsx") -> M_013.xlsx | F9: ='[1]Template '!$C$2 -> D only | H9: ='[1]Template '!$C$29 -> 0 | I9: ='[1]Template '!$C$30 -> n/a | J9: ='[1]Template '!$C$31 -> 0.33333333 | K9: ='[1]Template '!$C$32 -> 0.58455882 | L9: ='[1]Template '!$C$33 -> 0 | N9: ='[1]Template '!$C$74 -> 0.51818182 | O9: ='[1]Template '!$C$75 -> n/a | P9: ='[1]Template '!$C$76 -> 0.42857143 | Q9: ='[1]Template '!$C$77 -> 0.48809524 | R9: ='[1]Template '!$C$78 -> 0.4781746 | T9: ='[1]Template '!$C$96 -> 0.58333333 | U9: ='[1]Template '!$C$97 -> 0.48518519 | V9: ='[1]Template '!$C$98 -> 0.5 | W9: ='[1]Template '!$C$99 -> 0.25252525 | X9: ='[1]Template '!$C$100 -> 0.65793651 | Z9: ='[1]Template '!$C$52 -> 0.55555556 | AA9: ='[1]Template '!$C$53 -> 0.48518519 | AB9: ='[1]Template '!$C$54 -> 0.5 | AC9: ='[1]Template '!$C$55 -> 0.3125 | AD9: ='[1]Template '!$C$56 -> 0.5547619 | AF9: ='[1]Template '!$Z$30 -> 0 | AG9: ='[1]Template '!$AB$75 -> 0 | AH9: ='[1]Template '!$AD$75 -> 0 | AI9: ='[1]Template '!$AF$75 -> 0 | AJ9: ='[1]Template '!$AR$97 -> 0 | AK9: ='[1]Template '!$AS$97 -> 0 | AL9: ='[1]Template '!$AZ$97 -> 0 | AM9: ='[1]Template '!$BB$97 -> 0 | AN9: ='[1]Template '!$AU$53 -> 0 | AO9: ='[1]Template '!$AV$53 -> 0 | AP9: ='[1]Template '!$AY$53 -> 0 | AQ9: ='[1]Template '!$AX$53 -> 0 | AR9: ='[1]Template '!$AZ$53 -> 0 | AS9: ='[1]Template '!$BF$53 -> 0
B10: M_014 | D10: =CONCATENATE(B10,".xlsx") -> M_014.xlsx | F10: ='[2]Template '!$C$2 -> D+M | H10: ='[2]Template '!$C$29 -> 0.38888889 | I10: ='[2]Template '!$C$30 -> n/a | J10: ='[2]Template '!$C$31 -> 0.41666667 | K10: ='[2]Template '!$C$32 -> 0.66911765 | L10: ='[2]Template '!$C$33 -> 0.76984127 | N10: ='[2]Template '!$C$74 -> 0.65454545 | O10: ='[2]Template '!$C$75 -> n/a | P10: ='[2]Template '!$C$76 -> 0.39285714 | Q10: ='[2]Template '!$C$77 -> 0.4047619 | R10: ='[2]Template '!$C$78 -> 0.74603175 | T10: ='[2]Template '!$C$96 -> 0.66666667 | U10: ='[2]Template '!$C$97 -> 0.40740741 | V10: ='[2]Template '!$C$98 -> 0.5 | W10: ='[2]Template '!$C$99 -> 0.46897547 | X10: ='[2]Template '!$C$100 -> 0.68333333 | Z10: ='[2]Template '!$C$52 -> 0.78571429 | AA10: ='[2]Template '!$C$53 -> 0.40740741 | AB10: ='[2]Template '!$C$54 -> 0.5 | AC10: ='[2]Template '!$C$55 -> 0.5 | AD10: ='[2]Template '!$C$56 -> 0.7468254 | AF10: ='[2]Template '!$Z$30 -> 0 | AG10: ='[2]Template '!$AB$75 -> 0 | AH10: ='[2]Template '!$AD$75 -> 0 | AI10: ='[2]Template '!$AF$75 -> 0 | AJ10: ='[2]Template '!$AR$97 -> 0 | AK10: ='[2]Template '!$AS$97 -> 0 | AL10: ='[2]Template '!$AZ$97 -> 0 | AM10: ='[2]Template '!$BB$97 -> 1 | AN10: ='[2]Template '!$AU$53 -> 1 | AO10: ='[2]Template '!$AV$53 -> 1 | AP10: ='[2]Template '!$AY$53 -> 1 | AQ10: ='[2]Template '!$AX$53 -> 1 | AR10: ='[2]Template '!$AZ$53 -> 0 | AS10: ='[2]Template '!$BF$53 -> 0
B11: M_021 | D11: =CONCATENATE(B11,".xlsx") -> M_021.xlsx | F11: ='[3]Template '!$C$2 -> D+M | H11: ='[3]Template '!$C$29 -> 0.38888889 | I11: ='[3]Template '!$C$30 -> n/a | J11: ='[3]Template '!$C$31 -> 0.33333333 | K11: ='[3]Template '!$C$32 -> 0.47794118 | L11: ='[3]Template '!$C$33 -> 0.67063492 | N11: ='[3]Template '!$C$74 -> 0.7 | O11: ='[3]Template '!$C$75 -> n/a | P11: ='[3]Template '!$C$76 -> 0.42857143 | Q11: ='[3]Template '!$C$77 -> 0.53422619 | R11: ='[3]Template '!$C$78 -> 0.78373016 | T11: ='[3]Template '!$C$96 -> 0.8 | U11: ='[3]Template '!$C$97 -> 0.72222222 | V11: ='[3]Template '!$C$98 -> 0.5 | W11: ='[3]Template '!$C$99 -> 0.21428571 | X11: ='[3]Template '!$C$100 -> 0.64603175 | Z11: ='[3]Template '!$C$52 -> 0.69444444 | AA11: ='[3]Template '!$C$53 -> 0.72222222 | AB11: ='[3]Template '!$C$54 -> 0.5 | AC11: ='[3]Template '!$C$55 -> 0.24107143 | AD11: ='[3]Template '!$C$56 -> 0.5765873 | AF11: ='[3]Template '!$Z$30 -> 0 | AG11: ='[3]Template '!$AB$75 -> 0 | AH11: ='[3]Template '!$AD$75 -> 0 | AI11: ='[3]Template '!$AF$75 -> 0 | AJ11: ='[3]Template '!$AR$97 -> 0.5 | AK11: ='[3]Template '!$AS$97 -> 0 | AL11: ='[3]Template '!$AZ$97 -> 0 | AM11: ='[3]Template '!$BB$97 -> 0 | AN11: ='[3]Template '!$AU$53 -> 0 | AO11: ='[3]Template '!$AV$53 -> 0 | AP11: ='[3]Template '!$AY$53 -> 0 | AQ11: ='[3]Template '!$AX$53 -> 0 | AR11: ='[3]Template '!$AZ$53 -> 0 | AS11: ='[3]Template '!$BF$53 -> 0
B12: M_022 | D12: =CONCATENATE(B12,".xlsx") -> M_022.xlsx | F12: ='[4]Template '!$C$2 -> D only | H12: ='[4]Template '!$C$29 -> 0.66666667 | I12: ='[4]Template '!$C$30 -> n/a | J12: ='[4]Template '!$C$31 -> 0.16666667 | K12: ='[4]Template '!$C$32 -> 0.54411765 | L12: ='[4]Template '!$C$33 -> 0.65873016 | N12: ='[4]Template '!$C$74 -> 0.51818182 | O12: ='[4]Template '!$C$75 -> n/a | P12: ='[4]Template '!$C$76 -> 0.21428571 | Q12: ='[4]Template '!$C$77 -> 0.11904762 | R12: ='[4]Template '!$C$78 -> 0.28769841 | T12: ='[4]Template '!$C$96 -> 0.64583333 | U12: ='[4]Template '!$C$97 -> 0.34074074 | V12: ='[4]Template '!$C$98 -> 0 | W12: ='[4]Template '!$C$99 -> 0.28787879 | X12: ='[4]Template '!$C$100 -> 0.79007937 | Z12: ='[4]Template '!$C$52 -> 0.7734127 | AA12: ='[4]Template '!$C$53 -> 0.34074074 | AB12: ='[4]Template '!$C$54 -> 0 | AC12: ='[4]Template '!$C$55 -> 0.43005952 | AD12: ='[4]Template '!$C$56 -> 0.60079365 | AF12: ='[4]Template '!$Z$30 -> 0 | AG12: ='[4]Template '!$AB$75 -> 0 | AH12: ='[4]Template '!$AD$75 -> 0 | AI12: ='[4]Template '!$AF$75 -> 0 | AJ12: ='[4]Template '!$AR$97 -> 1 | AK12: ='[4]Template '!$AS$97 -> 1 | AL12: ='[4]Template '!$AZ$97 -> 0.5 | AM12: ='[4]Template '!$BB$97 -> 0 | AN12: ='[4]Template '!$AU$53 -> 0.5 | AO12: ='[4]Template '!$AV$53 -> 0.5 | AP12: ='[4]Template '!$AY$53 -> 0 | AQ12: ='[4]Template '!$AX$53 -> 0.5 | AR12: ='[4]Template '!$AZ$53 -> 1 | AS12: ='[4]Template '!$BF$53 -> 0.5
B13: M_024 | D13: =CONCATENATE(B13,".xlsx") -> M_024.xlsx | F13: ='[5]Template '!$C$2 -> D only | H13: ='[5]Template '!$C$29 -> 0 | I13: ='[5]Template '!$C$30 -> n/a | J13: ='[5]Template '!$C$31 -> 0 | K13: ='[5]Template '!$C$32 -> 0.23529412 | L13: ='[5]Template '!$C$33 -> 0.48214286 | N13: ='[5]Template '!$C$74 -> 0.65454545 | O13: ='[5]Template '!$C$75 -> n/a | P13: ='[5]Template '!$C$76 -> 0.071428571 | Q13: ='[5]Template '!$C$77 -> 0.46428571 | R13: ='[5]Template '!$C$78 -> 0.50595238 | T13: ='[5]Template '!$C$96 -> 0.65625 | U13: ='[5]Template '!$C$97 -> 0.30740741 | V13: ='[5]Template '!$C$98 -> 0 | W13: ='[5]Template '!$C$99 -> 0.34235209 | X13: ='[5]Template '!$C$100 -> 0.61190476 | Z13: ='[5]Template '!$C$52 -> 0 | AA13: ='[5]Template '!$C$53 -> 0.30740741 | AB13: ='[5]Template '!$C$54 -> 0 | AC13: ='[5]Template '!$C$55 -> 0.32142857 | AD13: ='[5]Template '!$C$56 -> 0.57857143 | AF13: ='[5]Template '!$Z$30 -> 0 | AG13: ='[5]Template '!$AB$75 -> 0 | AH13: ='[5]Template '!$AD$75 -> 0 | AI13: ='[5]Template '!$AF$75 -> 0 | AJ13: ='[5]Template '!$AR$97 -> 0 | AK13: ='[5]Template '!$AS$97 -> 0 | AL13: ='[5]Template '!$AZ$97 -> 0 | AM13: ='[5]Template '!$BB$97 -> 0 | AN13: ='[5]Template '!$AU$53 -> 0 | AO13: ='[5]Template '!$AV$53 -> 0 | AP13: ='[5]Template '!$AY$53 -> 0 | AQ13: ='[5]Template '!$AX$53 -> 0 | AR13: ='[5]Template '!$AZ$53 -> 0 | AS13: ='[5]Template '!$BF$53 -> 0
B14: M_027 | D14: =CONCATENATE(B14,".xlsx") -> M_027.xlsx | F14: D+M | H14: 0.44444444 | I14: n/a | J14: 0.33333333 | K14: 0.66911765 | L14: 0.88293651 | N14: 0.7 | O14: n/a | P14: 0.28571429 | Q14: 0.47619048 | R14: 0.75396825 | T14: 0.72708333 | U14: 0.41111111 | V14: 0 | W14: 0.61183261 | X14: 0.89484127 | Z14: 0.83690476 | AA14: 0.41111111 | AB14: 0.5 | AC14: 0.38425926 | AD14: 0.76825397 | AF14: 0 | AG14: 0 | AH14: 0 | AI14: 0 | AJ14: 1 | AK14: 0.5 | AL14: 1 | AM14: 0 | AN14: 0 | AO14: 0 | AP14: 0 | AQ14: 0 | AR14: 1 | AS14: 0
B15: M_028 | D15: =CONCATENATE(B15,".xlsx") -> M_028.xlsx | F15: ='[6]Template '!$C$2 -> D+M | H15: ='[6]Template '!$C$29 -> 0.41666667 | I15: ='[6]Template '!$C$30 -> n/a | J15: ='[6]Template '!$C$31 -> 0.83333333 | K15: ='[6]Template '!$C$32 -> 0.49183007 | L15: ='[6]Template '!$C$33 -> 0.75198413 | N15: ='[6]Template '!$C$74 -> 0.65454545 | O15: ='[6]Template '!$C$75 -> n/a | P15: ='[6]Template '!$C$76 -> 0.71428571 | Q15: ='[6]Template '!$C$77 -> 0.73809524 | R15: ='[6]Template '!$C$78 -> 0.86706349 | T15: ='[6]Template '!$C$96 -> 0.75 | U15: ='[6]Template '!$C$97 -> 0.53703704 | V15: ='[6]Template '!$C$98 -> 1 | W15: ='[6]Template '!$C$99 -> 0.49278499 | X15: ='[6]Template '!$C$100 -> 0.68134921 | Z15: ='[6]Template '!$C$52 -> 0.75 | AA15: ='[6]Template '!$C$53 -> 0.53703704 | AB15: ='[6]Template '!$C$54 -> 0 | AC15: ='[6]Template '!$C$55 -> 0.13541667 | AD15: ='[6]Template '!$C$56 -> 0.75674603 | AF15: ='[6]Template '!$Z$30 -> 0 | AG15: ='[6]Template '!$AB$75 -> 1 | AH15: ='[6]Template '!$AD$75 -> 1 | AI15: ='[6]Template '!$AF$75 -> 0 | AJ15: ='[6]Template '!$AR$97 -> 0 | AK15: ='[6]Template '!$AS$97 -> 0 | AL15: ='[6]Template '!$AZ$97 -> 0.5 | AM15: ='[6]Template '!$BB$97 -> 0.5 | AN15: ='[6]Template '!$AU$53 -> 0 | AO15: ='[6]Template '!$AV$53 -> 0 | AP15: ='[6]Template '!$AY$53 -> 0 | AQ15: ='[6]Template '!$AX$53 -> 0 | AR15: ='[6]Template '!$AZ$53 -> 0 | AS15: ='[6]Template '!$BF$53 -> 0
B16: M_029 | D16: =CONCATENATE(B16,".xlsx") -> M_029.xlsx | F16: ='[7]Template '!$C$2 -> D+M | H16: ='[7]Template '!$C$29 -> 0.83333333 | I16: ='[7]Template '!$C$30 -> n/a | J16: ='[7]Template '!$C$31 -> 0.41666667 | K16: ='[7]Template '!$C$32 -> 0.61029412 | L16: ='[7]Template '!$C$33 -> 0.59126984 | N16: ='[7]Template '!$C$74 -> 0.49545455 | O16: ='[7]Template '!$C$75 -> n/a | P16: ='[7]Template '!$C$76 -> 0.035714286 | Q16: ='[7]Template '!$C$77 -> 0.47619048 | R16: ='[7]Template '!$C$78 -> 0.44246032 | T16: ='[7]Template '!$C$96 -> 0.6875 | U16: ='[7]Template '!$C$97 -> 0.37407407 | V16: ='[7]Template '!$C$98 -> 0.5 | W16: ='[7]Template '!$C$99 -> 0.35425685 | X16: ='[7]Template '!$C$100 -> 0.51904762 | Z16: ='[7]Template '!$C$52 -> 0.68055556 | AA16: ='[7]Template '!$C$53 -> 0.37407407 | AB16: ='[7]Template '!$C$54 -> 0.5 | AC16: ='[7]Template '!$C$55 -> 0.27083333 | AD16: ='[7]Template '!$C$56 -> 0.65 | AF16: ='[7]Template '!$Z$30 -> 0 | AG16: ='[7]Template '!$AB$75 -> 0 | AH16: ='[7]Template '!$AD$75 -> 0 | AI16: ='[7]Template '!$AF$75 -> 0 | AJ16: ='[7]Template '!$AR$97 -> 0 | AK16: ='[7]Template '!$AS$97 -> 0 | AL16: ='[7]Template '!$AZ$97 -> 0 | AM16: ='[7]Template '!$BB$97 -> 0 | AN16: ='[7]Template '!$AU$53 -> 0 | AO16: ='[7]Template '!$AV$53 -> 0 | AP16: ='[7]Template '!$AY$53 -> 0 | AQ16: ='[7]Template '!$AX$53 -> 0 | AR16: ='[7]Template '!$AZ$53 -> 0 | AS16: ='[7]Template '!$BF$53 -> 0
B17: M_030 | D17: =CONCATENATE(B17,".xlsx") -> M_030.xlsx | F17: ='[8]Template '!$C$2 -> D+M | H17: ='[8]Template '!$C$29 -> 0.38888889 | I17: ='[8]Template '!$C$30 -> n/a | J17: ='[8]Template '!$C$31 -> 0.58333333 | K17: ='[8]Template '!$C$32 -> 0.51470588 | L17: ='[8]Template '!$C$33 -> 0.58333333 | N17: ='[8]Template '!$C$74 -> 0.65454545 | O17: ='[8]Template '!$C$75 -> n/a | P17: ='[8]Template '!$C$76 -> 0.5 | Q17: ='[8]Template '!$C$77 -> 0.48809524 | R17: ='[8]Template '!$C$78 -> 0.68253968 | T17: ='[8]Template '!$C$96 -> 0.70833333 | U17: ='[8]Template '!$C$97 -> 0.44444444 | V17: ='[8]Template '!$C$98 -> 0.25 | W17: ='[8]Template '!$C$99 -> 0.4387361 | X17: ='[8]Template '!$C$100 -> 0.70515873 | Z17: ='[8]Template '!$C$52 -> 0.70833333 | AA17: ='[8]Template '!$C$53 -> 0.44444444 | AB17: ='[8]Template '!$C$54 -> 0 | AC17: ='[8]Template '!$C$55 -> 0.52083333 | AD17: ='[8]Template '!$C$56 -> 0.68333333 | AF17: ='[8]Template '!$Z$30 -> 0 | AG17: ='[8]Template '!$AB$75 -> 0 | AH17: ='[8]Template '!$AD$75 -> 0 | AI17: ='[8]Template '!$AF$75 -> 0 | AJ17: ='[8]Template '!$AR$97 -> 0 | AK17: ='[8]Template '!$AS$97 -> 1 | AL17: ='[8]Template '!$AZ$97 -> 0 | AM17: ='[8]Template '!$BB$97 -> 0 | AN17: ='[8]Template '!$AU$53 -> 1 | AO17: ='[8]Template '!$AV$53 -> 0 | AP17: ='[8]Template '!$AY$53 -> 0 | AQ17: ='[8]Template '!$AX$53 -> 0 | AR17: ='[8]Template '!$AZ$53 -> 0 | AS17: ='[8]Template '!$BF$53 -> 0.5
B18: M_031 | D18: =CONCATENATE(B18,".xlsx") -> M_031.xlsx | F18: ='[9]Template '!$C$2 -> D only | H18: ='[9]Template '!$C$29 -> 0.66666667 | I18: ='[9]Template '!$C$30 -> n/a | J18: ='[9]Template '!$C$31 -> 0.58333333 | K18: ='[9]Template '!$C$32 -> 0.19117647 | L18: ='[9]Template '!$C$33 -> 0.3452381 | N18: ='[9]Template '!$C$74 -> 0.47272727 | O18: ='[9]Template '!$C$75 -> n/a | P18: ='[9]Template '!$C$76 -> 0.42857143 | Q18: ='[9]Template '!$C$77 -> 0.54761905 | R18: ='[9]Template '!$C$78 -> 0.36111111 | T18: ='[9]Template '!$C$96 -> 0.8 | U18: ='[9]Template '!$C$97 -> 0.38148148 | V18: ='[9]Template '!$C$98 -> 0.5 | W18: ='[9]Template '!$C$99 -> 0.20995671 | X18: ='[9]Template '!$C$100 -> 0.55555556 | Z18: ='[9]Template '!$C$52 -> 0.21349206 | AA18: ='[9]Template '!$C$53 -> 0.38148148 | AB18: ='[9]Template '!$C$54 -> 0.5 | AC18: ='[9]Template '!$C$55 -> 0.23958333 | AD18: ='[9]Template '!$C$56 -> 0.32777778 | AF18: ='[9]Template '!$Z$30 -> 0 | AG18: ='[9]Template '!$AB$75 -> 1 | AH18: ='[9]Template '!$AD$75 -> 0 | AI18: ='[9]Template '!$AF$75 -> 0 | AJ18: ='[9]Template '!$AR$97 -> 0 | AK18: ='[9]Template '!$AS$97 -> 1 | AL18: ='[9]Template '!$AZ$97 -> 0 | AM18: ='[9]Template '!$BB$97 -> 0 | AN18: ='[9]Template '!$AU$53 -> 0 | AO18: ='[9]Template '!$AV$53 -> 0 | AP18: ='[9]Template '!$AY$53 -> 0 | AQ18: ='[9]Template '!$AX$53 -> 0 | AR18: ='[9]Template '!$AZ$53 -> 0 | AS18: ='[9]Template '!$BF$53 -> 0
B19: M_032 | D19: =CONCATENATE(B19,".xlsx") -> M_032.xlsx | F19: ='[10]Template '!$C$2 -> D+M | H19: ='[10]Template '!$C$29 -> 0.41666667 | I19: ='[10]Template '!$C$30 -> n/a | J19: ='[10]Template '!$C$31 -> 0.25 | K19: ='[10]Template '!$C$32 -> 0.875 | L19: ='[10]Template '!$C$33 -> 0.95833333 | N19: ='[10]Template '!$C$74 -> 0.7 | O19: ='[10]Template '!$C$75 -> n/a | P19: ='[10]Template '!$C$76 -> 0.53571429 | Q19: ='[10]Template '!$C$77 -> 0.64285714 | R19: ='[10]Template '!$C$78 -> 0.83928571 | T19: ='[10]Template '!$C$96 -> 0.8 | U19: ='[10]Template '!$C$97 -> 0.57777778 | V19: ='[10]Template '!$C$98 -> 0.5 | W19: ='[10]Template '!$C$99 -> 0.78626602 | X19: ='[10]Template '!$C$100 -> 0.90714286 | Z19: ='[10]Template '!$C$52 -> 0.69444444 | AA19: ='[10]Template '!$C$53 -> 0.57777778 | AB19: ='[10]Template '!$C$54 -> 0.5 | AC19: ='[10]Template '!$C$55 -> 0.3125 | AD19: ='[10]Template '!$C$56 -> 0.90674603 | AF19: ='[10]Template '!$Z$30 -> 1 | AG19: ='[10]Template '!$AB$75 -> 0 | AH19: ='[10]Template '!$AD$75 -> 1 | AI19: ='[10]Template '!$AF$75 -> 0 | AJ19: ='[10]Template '!$AR$97 -> 1 | AK19: ='[10]Template '!$AS$97 -> 1 | AL19: ='[10]Template '!$AZ$97 -> 1 | AM19: ='[10]Template '!$BB$97 -> 1 | AN19: ='[10]Template '!$AU$53 -> 1 | AO19: ='[10]Template '!$AV$53 -> 1 | AP19: ='[10]Template '!$AY$53 -> 0.5 | AQ19: ='[10]Template '!$AX$53 -> 1 | AR19: ='[10]Template '!$AZ$53 -> 0 | AS19: ='[10]Template '!$BF$53 -> 0
B20: M_033 | D20: =CONCATENATE(B20,".xlsx") -> M_033.xlsx | F20: ='[11]Template '!$C$2 -> D only | H20: ='[11]Template '!$C$29 -> 0 | I20: ='[11]Template '!$C$30 -> n/a | J20: ='[11]Template '!$C$31 -> 0.41666667 | K20: ='[11]Template '!$C$32 -> 0.56617647 | L20: ='[11]Template '!$C$33 -> 0.65873016 | N20: ='[11]Template '!$C$74 -> 0.29090909 | O20: ='[11]Template '!$C$75 -> n/a | P20: ='[11]Template '!$C$76 -> 0.35714286 | Q20: ='[11]Template '!$C$77 -> 0.46428571 | R20: ='[11]Template '!$C$78 -> 0.62103175 | T20: ='[11]Template '!$C$96 -> 0.40625 | U20: ='[11]Template '!$C$97 -> 0.24444444 | V20: ='[11]Template '!$C$98 -> 0.5 | W20: ='[11]Template '!$C$99 -> 0.3001443 | X20: ='[11]Template '!$C$100 -> 0.63650794 | Z20: ='[11]Template '!$C$52 -> 0.14166667 | AA20: ='[11]Template '!$C$53 -> 0.24444444 | AB20: ='[11]Template '!$C$54 -> 0.5 | AC20: ='[11]Template '!$C$55 -> 0.25 | AD20: ='[11]Template '!$C$56 -> 0.6702381 | AF20: ='[11]Template '!$Z$30 -> 0 | AG20: ='[11]Template '!$AB$75 -> 0 | AH20: ='[11]Template '!$AD$75 -> 0 | AI20: ='[11]Template '!$AF$75 -> 0 | AJ20: ='[11]Template '!$AR$97 -> 0 | AK20: ='[11]Template '!$AS$97 -> 0 | AL20: ='[11]Template '!$AZ$97 -> 0 | AM20: ='[11]Template '!$BB$97 -> 0 | AN20: ='[11]Template '!$AU$53 -> 0 | AO20: ='[11]Template '!$AV$53 -> 0 | AP20: ='[11]Template '!$AY$53 -> 0 | AQ20: ='[11]Template '!$AX$53 -> 0 | AR20: ='[11]Template '!$AZ$53 -> 0 | AS20: ='[11]Template '!$BF$53 -> 0
B21: M_034 | D21: =CONCATENATE(B21,".xlsx") -> M_034.xlsx | F21: ='[12]Template '!$C$2 -> D+M | H21: ='[12]Template '!$C$29 -> 0.38888889 | I21: ='[12]Template '!$C$30 -> n/a | J21: ='[12]Template '!$C$31 -> 0.66666667 | K21: ='[12]Template '!$C$32 -> 0.60294118 | L21: ='[12]Template '!$C$33 -> 0.78968254 | N21: ='[12]Template '!$C$74 -> 0.63181818 | O21: ='[12]Template '!$C$75 -> n/a | P21: ='[12]Template '!$C$76 -> 0.21428571 | Q21: ='[12]Template '!$C$77 -> 0.48809524 | R21: ='[12]Template '!$C$78 -> 0.71031746 | T21: ='[12]Template '!$C$96 -> 0.71875 | U21: ='[12]Template '!$C$97 -> 0.47407407 | V21: ='[12]Template '!$C$98 -> 0.5 | W21: ='[12]Template '!$C$99 -> 0.44408369 | X21: ='[12]Template '!$C$100 -> 0.74246032 | Z21: ='[12]Template '!$C$52 -> 0.72222222 | AA21: ='[12]Template '!$C$53 -> 0.47407407 | AB21: ='[12]Template '!$C$54 -> 0.5 | AC21: ='[12]Template '!$C$55 -> 0.34375 | AD21: ='[12]Template '!$C$56 -> 0.84563492 | AF21: ='[12]Template '!$Z$30 -> 0 | AG21: ='[12]Template '!$AB$75 -> 0 | AH21: ='[12]Template '!$AD$75 -> 0 | AI21: ='[12]Template '!$AF$75 -> 0 | AJ21: ='[12]Template '!$AR$97 -> 0.5 | AK21: ='[12]Template '!$AS$97 -> 0 | AL21: ='[12]Template '!$AZ$97 -> 0 | AM21: ='[12]Template '!$BB$97 -> 0 | AN21: ='[12]Template '!$AU$53 -> 0.5 | AO21: ='[12]Template '!$AV$53 -> 0.5 | AP21: ='[12]Template '!$AY$53 -> 0 | AQ21: ='[12]Template '!$AX$53 -> 0 | AR21: ='[12]Template '!$AZ$53 -> 0 | AS21: ='[12]Template '!$BF$53 -> 0
B22: M_035 | D22: =CONCATENATE(B22,".xlsx") -> M_035.xlsx | F22: ='[13]Template '!$C$2 -> D only | H22: ='[13]Template '!$C$29 -> 0.27777778 | I22: ='[13]Template '!$C$30 -> n/a | J22: ='[13]Template '!$C$31 -> 0.33333333 | K22: ='[13]Template '!$C$32 -> 0.48529412 | L22: ='[13]Template '!$C$33 -> 0.50396825 | N22: ='[13]Template '!$C$74 -> 0.51818182 | O22: ='[13]Template '!$C$75 -> n/a | P22: ='[13]Template '!$C$76 -> 0 | Q22: ='[13]Template '!$C$77 -> 0.19047619 | R22: ='[13]Template '!$C$78 -> 0.25 | T22: ='[13]Template '!$C$96 -> 0.26041667 | U22: ='[13]Template '!$C$97 -> 0.27407407 | V22: ='[13]Template '!$C$98 -> 0.5 | W22: ='[13]Template '!$C$99 -> 0.060606061 | X22: ='[13]Template '!$C$100 -> 0.2015873 | Z22: ='[13]Template '!$C$52 -> 0 | AA22: ='[13]Template '!$C$53 -> 0.27407407 | AB22: ='[13]Template '!$C$54 -> 0 | AC22: ='[13]Template '!$C$55 -> 0 | AD22: ='[13]Template '!$C$56 -> 0.24166667 | AF22: ='[13]Template '!$Z$30 -> 0 | AG22: ='[13]Template '!$AB$75 -> 0 | AH22: ='[13]Template '!$AD$75 -> 0 | AI22: ='[13]Template '!$AF$75 -> 0 | AJ22: ='[13]Template '!$AR$97 -> 0 | AK22: ='[13]Template '!$AS$97 -> 0 | AL22: ='[13]Template '!$AZ$97 -> 0 | AM22: ='[13]Template '!$BB$97 -> 0 | AN22: ='[13]Template '!$AU$53 -> 0 | AO22: ='[13]Template '!$AV$53 -> 0 | AP22: ='[13]Template '!$AY$53 -> 0 | AQ22: ='[13]Template '!$AX$53 -> 0 | AR22: ='[13]Template '!$AZ$53 -> 0 | AS22: ='[13]Template '!$BF$53 -> 0
B23: M_036 | D23: =CONCATENATE(B23,".xlsx") -> M_036.xlsx | F23: ='[14]Template '!$C$2 -> D only | H23: ='[14]Template '!$C$29 -> 0.055555556 | I23: ='[14]Template '!$C$30 -> n/a | J23: ='[14]Template '!$C$31 -> 0.25 | K23: ='[14]Template '!$C$32 -> 0.41176471 | L23: ='[14]Template '!$C$33 -> 0.51388889 | N23: ='[14]Template '!$C$74 -> 0.38181818 | O23: ='[14]Template '!$C$75 -> n/a | P23: ='[14]Template '!$C$76 -> 0.14285714 | Q23: ='[14]Template '!$C$77 -> 0.5 | R23: ='[14]Template '!$C$78 -> 0.66666667 | T23: ='[14]Template '!$C$96 -> 0.19583333 | U23: ='[14]Template '!$C$97 -> 0.57777778 | V23: ='[14]Template '!$C$98 -> 0 | W23: ='[14]Template '!$C$99 -> 0.22222222 | X23: ='[14]Template '!$C$100 -> 0.47301587 | Z23: ='[14]Template '!$C$52 -> 0.27777778 | AA23: ='[14]Template '!$C$53 -> 0.57777778 | AB23: ='[14]Template '!$C$54 -> 0.25 | AC23: ='[14]Template '!$C$55 -> 0.27083333 | AD23: ='[14]Template '!$C$56 -> 0.47936508 | AF23: ='[14]Template '!$Z$30 -> 0 | AG23: ='[14]Template '!$AB$75 -> 0 | AH23: ='[14]Template '!$AD$75 -> 1 | AI23: ='[14]Template '!$AF$75 -> 0 | AJ23: ='[14]Template '!$AR$97 -> 0 | AK23: ='[14]Template '!$AS$97 -> 0 | AL23: ='[14]Template '!$AZ$97 -> 0 | AM23: ='[14]Template '!$BB$97 -> 0 | AN23: ='[14]Template '!$AU$53 -> 0 | AO23: ='[14]Template '!$AV$53 -> 0 | AP23: ='[14]Template '!$AY$53 -> 0 | AQ23: ='[14]Template '!$AX$53 -> 0 | AR23: ='[14]Template '!$AZ$53 -> 0.5 | AS23: ='[14]Template '!$BF$53 -> 0
B24: M_038 | D24: =CONCATENATE(B24,".xlsx") -> M_038.xlsx | F24: ='[15]Template '!$C$2 -> D+M | H24: ='[15]Template '!$C$29 -> 0.5 | I24: ='[15]Template '!$C$30 -> n/a | J24: ='[15]Template '!$C$31 -> 0.33333333 | K24: ='[15]Template '!$C$32 -> 0.60294118 | L24: ='[15]Template '!$C$33 -> 0.79365079 | N24: ='[15]Template '!$C$74 -> 0.51818182 | O24: ='[15]Template '!$C$75 -> n/a | P24: ='[15]Template '!$C$76 -> 0.46428571 | Q24: ='[15]Template '!$C$77 -> 0.5 | R24: ='[15]Template '!$C$78 -> 0.87301587 | T24: ='[15]Template '!$C$96 -> 0.35416667 | U24: ='[15]Template '!$C$97 -> 0.65185185 | V24: ='[15]Template '!$C$98 -> 0 | W24: ='[15]Template '!$C$99 -> 0.33706816 | X24: ='[15]Template '!$C$100 -> 0.9047619 | Z24: ='[15]Template '!$C$52 -> 0.49365079 | AA24: ='[15]Template '!$C$53 -> 0.65185185 | AB24: ='[15]Template '!$C$54 -> 0 | AC24: ='[15]Template '!$C$55 -> 0.33035714 | AD24: ='[15]Template '!$C$56 -> 0.81428571 | AF24: ='[15]Template '!$Z$30 -> 0 | AG24: ='[15]Template '!$AB$75 -> 0 | AH24: ='[15]Template '!$AD$75 -> 0 | AI24: ='[15]Template '!$AF$75 -> 0 | AJ24: ='[15]Template '!$AR$97 -> 0 | AK24: ='[15]Template '!$AS$97 -> 0 | AL24: ='[15]Template '!$AZ$97 -> 0 | AM24: ='[15]Template '!$BB$97 -> 0 | AN24: ='[15]Template '!$AU$53 -> 0 | AO24: ='[15]Template '!$AV$53 -> 0 | AP24: ='[15]Template '!$AY$53 -> 0 | AQ24: ='[15]Template '!$AX$53 -> 0 | AR24: ='[15]Template '!$AZ$53 -> 1 | AS24: ='[15]Template '!$BF$53 -> 0
B25: M_039 | D25: =CONCATENATE(B25,".xlsx") -> M_039.xlsx | F25: ='[16]Template '!$C$2 -> D only | H25: ='[16]Template '!$C$29 -> 0 | I25: ='[16]Template '!$C$30 -> n/a | J25: ='[16]Template '!$C$31 -> 0.25 | K25: ='[16]Template '!$C$32 -> 0.20588235 | L25: ='[16]Template '!$C$33 -> 0.4484127 | N25: ='[16]Template '!$C$74 -> 0.51818182 | O25: ='[16]Template '!$C$75 -> n/a | P25: ='[16]Template '!$C$76 -> 0.14285714 | Q25: ='[16]Template '!$C$77 -> 0.46428571 | R25: ='[16]Template '!$C$78 -> 0.50396825 | T25: ='[16]Template '!$C$96 -> 0.44583333 | U25: ='[16]Template '!$C$97 -> 0.37777778 | V25: ='[16]Template '!$C$98 -> 0.5 | W25: ='[16]Template '!$C$99 -> 0.43867244 | X25: ='[16]Template '!$C$100 -> 0.71349206 | Z25: ='[16]Template '!$C$52 -> 0.37698413 | AA25: ='[16]Template '!$C$53 -> 0.37777778 | AB25: ='[16]Template '!$C$54 -> 0 | AC25: ='[16]Template '!$C$55 -> 0.3125 | AD25: ='[16]Template '!$C$56 -> 0.54920635 | AF25: ='[16]Template '!$Z$30 -> 0 | AG25: ='[16]Template '!$AB$75 -> 0 | AH25: ='[16]Template '!$AD$75 -> 0 | AI25: ='[16]Template '!$AF$75 -> 0 | AJ25: ='[16]Template '!$AR$97 -> 0.5 | AK25: ='[16]Template '!$AS$97 -> 0 | AL25: ='[16]Template '!$AZ$97 -> 0.5 | AM25: ='[16]Template '!$BB$97 -> 0 | AN25: ='[16]Template '!$AU$53 -> 0 | AO25: ='[16]Template '!$AV$53 -> 0 | AP25: ='[16]Template '!$AY$53 -> 0 | AQ25: ='[16]Template '!$AX$53 -> 0 | AR25: ='[16]Template '!$AZ$53 -> 0 | AS25: ='[16]Template '!$BF$53 -> 0
B26: M_040 | D26: =CONCATENATE(B26,".xlsx") -> M_040.xlsx | F26: ='[17]Template '!$C$2 -> D only | H26: ='[17]Template '!$C$29 -> 0.33333333 | I26: ='[17]Template '!$C$30 -> n/a | J26: ='[17]Template '!$C$31 -> 0.58333333 | K26: ='[17]Template '!$C$32 -> 0.77205882 | L26: ='[17]Template '!$C$33 -> 0.66468254 | N26: ='[17]Template '!$C$74 -> 0.7 | O26: ='[17]Template '!$C$75 -> n/a | P26: ='[17]Template '!$C$76 -> 0.42857143 | Q26: ='[17]Template '!$C$77 -> 0.71428571 | R26: ='[17]Template '!$C$78 -> 0.85515873 | T26: ='[17]Template '!$C$96 -> 0.54166667 | U26: ='[17]Template '!$C$97 -> 0.5037037 | V26: ='[17]Template '!$C$98 -> 0.5 | W26: ='[17]Template '!$C$99 -> 0.40836941 | X26: ='[17]Template '!$C$100 -> 0.75396825 | Z26: ='[17]Template '!$C$52 -> 0.69444444 | AA26: ='[17]Template '!$C$53 -> 0.5037037 | AB26: ='[17]Template '!$C$54 -> 0.5 | AC26: ='[17]Template '!$C$55 -> 0.54464286 | AD26: ='[17]Template '!$C$56 -> 0.7484127 | AF26: ='[17]Template '!$Z$30 -> 0.5 | AG26: ='[17]Template '!$AB$75 -> 1 | AH26: ='[17]Template '!$AD$75 -> 1 | AI26: ='[17]Template '!$AF$75 -> 1 | AJ26: ='[17]Template '!$AR$97 -> 0.5 | AK26: ='[17]Template '!$AS$97 -> 0 | AL26: ='[17]Template '!$AZ$97 -> 0 | AM26: ='[17]Template '!$BB$97 -> 0 | AN26: ='[17]Template '!$AU$53 -> 1 | AO26: ='[17]Template '!$AV$53 -> 0 | AP26: ='[17]Template '!$AY$53 -> 0 | AQ26: ='[17]Template '!$AX$53 -> 0 | AR26: ='[17]Template '!$AZ$53 -> 0 | AS26: ='[17]Template '!$BF$53 -> 0.5
B27: M_041 | D27: =CONCATENATE(B27,".xlsx") -> M_041.xlsx | F27: ='[18]Template '!$C$2 -> D only | H27: ='[18]Template '!$C$29 -> 0.11111111 | I27: ='[18]Template '!$C$30 -> n/a | J27: ='[18]Template '!$C$31 -> 0.58333333 | K27: ='[18]Template '!$C$32 -> 0.66911765 | L27: ='[18]Template '!$C$33 -> 0.57936508 | N27: ='[18]Template '!$C$74 -> 0.23636364 | O27: ='[18]Template '!$C$75 -> n/a | P27: ='[18]Template '!$C$76 -> 0.46428571 | Q27: ='[18]Template '!$C$77 -> 0.46428571 | R27: ='[18]Template '!$C$78 -> 0.60119048 | T27: ='[18]Template '!$C$96 -> 0.37291667 | U27: ='[18]Template '!$C$97 -> 0.60740741 | V27: ='[18]Template '!$C$98 -> 0.5 | W27: ='[18]Template '!$C$99 -> 0.4505772 | X27: ='[18]Template '!$C$100 -> 0.7031746 | Z27: ='[18]Template '!$C$52 -> 0.31507937 | AA27: ='[18]Template '!$C$53 -> 0.60740741 | AB27: ='[18]Template '!$C$54 -> 0.5 | AC27: ='[18]Template '!$C$55 -> 0.125 | AD27: ='[18]Template '!$C$56 -> 0.71904762 | AF27: ='[18]Template '!$Z$30 -> 0 | AG27: ='[18]Template '!$AB$75 -> 0 | AH27: ='[18]Template '!$AD$75 -> 0 | AI27: ='[18]Template '!$AF$75 -> 0 | AJ27: ='[18]Template '!$AR$97 -> 0 | AK27: ='[18]Template '!$AS$97 -> 0.5 | AL27: ='[18]Template '!$AZ$97 -> 0 | AM27: ='[18]Template '!$BB$97 -> 0 | AN27: ='[18]Template '!$AU$53 -> 0 | AO27: ='[18]Template '!$AV$53 -> 0 | AP27: ='[18]Template '!$AY$53 -> 0 | AQ27: ='[18]Template '!$AX$53 -> 0 | AR27: ='[18]Template '!$AZ$53 -> 0 | AS27: ='[18]Template '!$BF$53 -> 0
B28: M_045 | D28: =CONCATENATE(B28,".xlsx") -> M_045.xlsx | F28: ='[19]Template '!$C$2 -> D+M | H28: ='[19]Template '!$C$29 -> 0.38888889 | I28: ='[19]Template '!$C$30 -> n/a | J28: ='[19]Template '!$C$31 -> 0.66666667 | K28: ='[19]Template '!$C$32 -> 0.54411765 | L28: ='[19]Template '!$C$33 -> 0.79960317 | N28: ='[19]Template '!$C$74 -> 0.54090909 | O28: ='[19]Template '!$C$75 -> n/a | P28: ='[19]Template '!$C$76 -> 0.39285714 | Q28: ='[19]Template '!$C$77 -> 0.47619048 | R28: ='[19]Template '!$C$78 -> 0.75595238 | T28: ='[19]Template '!$C$96 -> 0.75 | U28: ='[19]Template '!$C$97 -> 0.44444444 | V28: ='[19]Template '!$C$98 -> 0.5 | W28: ='[19]Template '!$C$99 -> 0.7027417 | X28: ='[19]Template '!$C$100 -> 0.8452381 | Z28: ='[19]Template '!$C$52 -> 0.66666667 | AA28: ='[19]Template '!$C$53 -> 0.44444444 | AB28: ='[19]Template '!$C$54 -> 0.5 | AC28: ='[19]Template '!$C$55 -> 0.33333333 | AD28: ='[19]Template '!$C$56 -> 0.88293651 | AF28: ='[19]Template '!$Z$30 -> 0 | AG28: ='[19]Template '!$AB$75 -> 0 | AH28: ='[19]Template '!$AD$75 -> 0 | AI28: ='[19]Template '!$AF$75 -> 0 | AJ28: ='[19]Template '!$AR$97 -> 0.5 | AK28: ='[19]Template '!$AS$97 -> 0 | AL28: ='[19]Template '!$AZ$97 -> 0.5 | AM28: ='[19]Template '!$BB$97 -> 1 | AN28: ='[19]Template '!$AU$53 -> 1 | AO28: ='[19]Template '!$AV$53 -> 1 | AP28: ='[19]Template '!$AY$53 -> 1 | AQ28: ='[19]Template '!$AX$53 -> 0 | AR28: ='[19]Template '!$AZ$53 -> 0 | AS28: ='[19]Template '!$BF$53 -> 0
B29: M_046 | D29: =CONCATENATE(B29,".xlsx") -> M_046.xlsx | F29: ='[20]Template '!$C$2 -> D+M | H29: ='[20]Template '!$C$29 -> 0.38888889 | I29: ='[20]Template '!$C$30 -> n/a | J29: ='[20]Template '!$C$31 -> 0.66666667 | K29: ='[20]Template '!$C$32 -> 0.72794118 | L29: ='[20]Template '!$C$33 -> 0.77777778 | N29: ='[20]Template '!$C$74 -> 0.7 | O29: ='[20]Template '!$C$75 -> n/a | P29: ='[20]Template '!$C$76 -> 0.53571429 | Q29: ='[20]Template '!$C$77 -> 0.61904762 | R29: ='[20]Template '!$C$78 -> 0.85119048 | T29: ='[20]Template '!$C$96 -> 0.75 | U29: ='[20]Template '!$C$97 -> 0.31111111 | V29: ='[20]Template '!$C$98 -> 0.5 | W29: ='[20]Template '!$C$99 -> 0.88888889 | X29: ='[20]Template '!$C$100 -> 0.9702381 | Z29: ='[20]Template '!$C$52 -> 0.75 | AA29: ='[20]Template '!$C$53 -> 0.31111111 | AB29: ='[20]Template '!$C$54 -> 0.5 | AC29: ='[20]Template '!$C$55 -> 0.70238095 | AD29: ='[20]Template '!$C$56 -> 0.90079365 | AF29: ='[20]Template '!$Z$30 -> 0 | AG29: ='[20]Template '!$AB$75 -> 0 | AH29: ='[20]Template '!$AD$75 -> 1 | AI29: ='[20]Template '!$AF$75 -> 0 | AJ29: ='[20]Template '!$AR$97 -> 1 | AK29: ='[20]Template '!$AS$97 -> 1 | AL29: ='[20]Template '!$AZ$97 -> 1 | AM29: ='[20]Template '!$BB$97 -> 1 | AN29: ='[20]Template '!$AU$53 -> 1 | AO29: ='[20]Template '!$AV$53 -> 1 | AP29: ='[20]Template '!$AY$53 -> 0 | AQ29: ='[20]Template '!$AX$53 -> 0 | AR29: ='[20]Template '!$AZ$53 -> 0 | AS29: ='[20]Template '!$BF$53 -> 1
B30: M_047 | D30: =CONCATENATE(B30,".xlsx") -> M_047.xlsx | F30: ='[21]Template '!$C$2 -> D+M | H30: ='[21]Template '!$C$29 -> 0.88888889 | I30: ='[21]Template '!$C$30 -> n/a | J30: ='[21]Template '!$C$31 -> 0.33333333 | K30: ='[21]Template '!$C$32 -> 0.72794118 | L30: ='[21]Template '!$C$33 -> 0.81746032 | N30: ='[21]Template '!$C$74 -> 0.51818182 | O30: ='[21]Template '!$C$75 -> n/a | P30: ='[21]Template '!$C$76 -> 0.28571429 | Q30: ='[21]Template '!$C$77 -> 0.5 | R30: ='[21]Template '!$C$78 -> 0.72619048 | T30: ='[21]Template '!$C$96 -> 0.46875 | U30: ='[21]Template '!$C$97 -> 0.31111111 | V30: ='[21]Template '!$C$98 -> 0 | W30: ='[21]Template '!$C$99 -> 0.61832612 | X30: ='[21]Template '!$C$100 -> 0.87142857 | Z30: ='[21]Template '!$C$52 -> 0.75 | AA30: ='[21]Template '!$C$53 -> 0.31111111 | AB30: ='[21]Template '!$C$54 -> 0 | AC30: ='[21]Template '!$C$55 -> 0.52380952 | AD30: ='[21]Template '!$C$56 -> 0.94047619 | AF30: ='[21]Template '!$Z$30 -> 0 | AG30: ='[21]Template '!$AB$75 -> 0 | AH30: ='[21]Template '!$AD$75 -> 0 | AI30: ='[21]Template '!$AF$75 -> 0 | AJ30: ='[21]Template '!$AR$97 -> 1 | AK30: ='[21]Template '!$AS$97 -> 1 | AL30: ='[21]Template '!$AZ$97 -> 0.5 | AM30: ='[21]Template '!$BB$97 -> 1 | AN30: ='[21]Template '!$AU$53 -> 0.5 | AO30: ='[21]Template '!$AV$53 -> 0 | AP30: ='[21]Template '!$AY$53 -> 0 | AQ30: ='[21]Template '!$AX$53 -> 0 | AR30: ='[21]Template '!$AZ$53 -> 0 | AS30: ='[21]Template '!$BF$53 -> 0.5
B31: M_048 | D31: =CONCATENATE(B31,".xlsx") -> M_048.xlsx | F31: ='[22]Template '!$C$2 -> D only | H31: ='[22]Template '!$C$29 -> 0.11111111 | I31: ='[22]Template '!$C$30 -> n/a | J31: ='[22]Template '!$C$31 -> 0.25 | K31: ='[22]Template '!$C$32 -> 0.48529412 | L31: ='[22]Template '!$C$33 -> 0.26785714 | N31: ='[22]Template '!$C$74 -> 0.29090909 | O31: ='[22]Template '!$C$75 -> n/a | P31: ='[22]Template '!$C$76 -> 0.28571429 | Q31: ='[22]Template '!$C$77 -> 0.54613095 | R31: ='[22]Template '!$C$78 -> 0.41071429 | T31: ='[22]Template '!$C$96 -> 0.3125 | U31: ='[22]Template '!$C$97 -> 0.3 | V31: ='[22]Template '!$C$98 -> 0.5 | W31: ='[22]Template '!$C$99 -> 0.2979798 | X31: ='[22]Template '!$C$100 -> 0.42698413 | Z31: ='[22]Template '!$C$52 -> 0.33333333 | AA31: ='[22]Template '!$C$53 -> 0.3 | AB31: ='[22]Template '!$C$54 -> 0.5 | AC31: ='[22]Template '!$C$55 -> 0.20833333 | AD31: ='[22]Template '!$C$56 -> 0.29047619 | AF31: ='[22]Template '!$Z$30 -> 0 | AG31: ='[22]Template '!$AB$75 -> 1 | AH31: ='[22]Template '!$AD$75 -> 0.5 | AI31: ='[22]Template '!$AF$75 -> 0 | AJ31: ='[22]Template '!$AR$97 -> 0 | AK31: ='[22]Template '!$AS$97 -> 0 | AL31: ='[22]Template '!$AZ$97 -> 0 | AM31: ='[22]Template '!$BB$97 -> 0 | AN31: ='[22]Template '!$AU$53 -> 0 | AO31: ='[22]Template '!$AV$53 -> 0 | AP31: ='[22]Template '!$AY$53 -> 0 | AQ31: ='[22]Template '!$AX$53 -> 0 | AR31: ='[22]Template '!$AZ$53 -> 0 | AS31: ='[22]Template '!$BF$53 -> 0
B32: M_049 | D32: =CONCATENATE(B32,".xlsx") -> M_049.xlsx | F32: ='[23]Template '!$C$2 -> D only | H32: ='[23]Template '!$C$29 -> 0 | I32: ='[23]Template '!$C$30 -> n/a | J32: ='[23]Template '!$C$31 -> 0.41666667 | K32: ='[23]Template '!$C$32 -> 0.39705882 | L32: ='[23]Template '!$C$33 -> 0.13293651 | N32: ='[23]Template '!$C$74 -> 0.29090909 | O32: ='[23]Template '!$C$75 -> n/a | P32: ='[23]Template '!$C$76 -> 0.39285714 | Q32: ='[23]Template '!$C$77 -> 0.5 | R32: ='[23]Template '!$C$78 -> 0.33928571 | T32: ='[23]Template '!$C$96 -> 0.16666667 | U32: ='[23]Template '!$C$97 -> 0.26666667 | V32: ='[23]Template '!$C$98 -> 0.5 | W32: ='[23]Template '!$C$99 -> 0.03030303 | X32: ='[23]Template '!$C$100 -> 0.15873016 | Z32: ='[23]Template '!$C$52 -> 0 | AA32: ='[23]Template '!$C$53 -> 0.26666667 | AB32: ='[23]Template '!$C$54 -> 0.5 | AC32: ='[23]Template '!$C$55 -> 0.16666667 | AD32: ='[23]Template '!$C$56 -> 0.31468254 | AF32: ='[23]Template '!$Z$30 -> 0 | AG32: ='[23]Template '!$AB$75 -> 0 | AH32: ='[23]Template '!$AD$75 -> 0 | AI32: ='[23]Template '!$AF$75 -> 0 | AJ32: ='[23]Template '!$AR$97 -> 0 | AK32: ='[23]Template '!$AS$97 -> 0 | AL32: ='[23]Template '!$AZ$97 -> 0 | AM32: ='[23]Template '!$BB$97 -> 0 | AN32: ='[23]Template '!$AU$53 -> 0 | AO32: ='[23]Template '!$AV$53 -> 0 | AP32: ='[23]Template '!$AY$53 -> 0 | AQ32: ='[23]Template '!$AX$53 -> 0 | AR32: ='[23]Template '!$AZ$53 -> 0 | AS32: ='[23]Template '!$BF$53 -> 0
B33: M_083 | D33: =CONCATENATE(B33,".xlsx") -> M_083.xlsx | F33: ='[24]Template '!$C$2 -> D+M | H33: ='[24]Template '!$C$29 -> 0.22222222 | I33: ='[24]Template '!$C$30 -> n/a | J33: ='[24]Template '!$C$31 -> 0 | K33: ='[24]Template '!$C$32 -> 0.60294118 | L33: ='[24]Template '!$C$33 -> 0.88492063 | N33: ='[24]Template '!$C$74 -> 0.60909091 | O33: ='[24]Template '!$C$75 -> n/a | P33: ='[24]Template '!$C$76 -> 0.21428571 | Q33: ='[24]Template '!$C$77 -> 0.52380952 | R33: ='[24]Template '!$C$78 -> 0.77380952 | T33: ='[24]Template '!$C$96 -> 0.4375 | U33: ='[24]Template '!$C$97 -> 0.51111111 | V33: ='[24]Template '!$C$98 -> 0.5 | W33: ='[24]Template '!$C$99 -> 0.64646465 | X33: ='[24]Template '!$C$100 -> 0.97619048 | Z33: ='[24]Template '!$C$52 -> 0.20555556 | AA33: ='[24]Template '!$C$53 -> 0.51111111 | AB33: ='[24]Template '!$C$54 -> 0 | AC33: ='[24]Template '!$C$55 -> 0.41666667 | AD33: ='[24]Template '!$C$56 -> 0.90873016 | AF33: ='[24]Template '!$Z$30 -> 0 | AG33: ='[24]Template '!$AB$75 -> 0 | AH33: ='[24]Template '!$AD$75 -> 0 | AI33: ='[24]Template '!$AF$75 -> 0 | AJ33: ='[24]Template '!$AR$97 -> 1 | AK33: ='[24]Template '!$AS$97 -> 1 | AL33: ='[24]Template '!$AZ$97 -> 0 | AM33: ='[24]Template '!$BB$97 -> 0 | AN33: ='[24]Template '!$AU$53 -> 1 | AO33: ='[24]Template '!$AV$53 -> 1 | AP33: ='[24]Template '!$AY$53 -> 0 | AQ33: ='[24]Template '!$AX$53 -> 1 | AR33: ='[24]Template '!$AZ$53 -> 0 | AS33: ='[24]Template '!$BF$53 -> 0
B34: M_084 | D34: =CONCATENATE(B34,".xlsx") -> M_084.xlsx | F34: ='[25]Template '!$C$2 -> D only | H34: ='[25]Template '!$C$29 -> 0.25 | I34: ='[25]Template '!$C$30 -> n/a | J34: ='[25]Template '!$C$31 -> 0.41666667 | K34: ='[25]Template '!$C$32 -> 0.63235294 | L34: ='[25]Template '!$C$33 -> 0.52579365 | N34: ='[25]Template '!$C$74 -> 0.38181818 | O34: ='[25]Template '!$C$75 -> n/a | P34: ='[25]Template '!$C$76 -> 0.48214286 | Q34: ='[25]Template '!$C$77 -> 0.54761905 | R34: ='[25]Template '!$C$78 -> 0.51984127 | T34: ='[25]Template '!$C$96 -> 0.4375 | U34: ='[25]Template '!$C$97 -> 0.34444444 | V34: ='[25]Template '!$C$98 -> 0.5 | W34: ='[25]Template '!$C$99 -> 0.48088023 | X34: ='[25]Template '!$C$100 -> 0.65992063 | Z34: ='[25]Template '!$C$52 -> 0.375 | AA34: ='[25]Template '!$C$53 -> 0.34444444 | AB34: ='[25]Template '!$C$54 -> 0.5 | AC34: ='[25]Template '!$C$55 -> 0.375 | AD34: ='[25]Template '!$C$56 -> 0.43650794 | AF34: ='[25]Template '!$Z$30 -> 1 | AG34: ='[25]Template '!$AB$75 -> 1 | AH34: ='[25]Template '!$AD$75 -> 0 | AI34: ='[25]Template '!$AF$75 -> 0 | AJ34: ='[25]Template '!$AR$97 -> 1 | AK34: ='[25]Template '!$AS$97 -> 0 | AL34: ='[25]Template '!$AZ$97 -> 1 | AM34: ='[25]Template '!$BB$97 -> 0 | AN34: ='[25]Template '!$AU$53 -> 1 | AO34: ='[25]Template '!$AV$53 -> 1 | AP34: ='[25]Template '!$AY$53 -> 0 | AQ34: ='[25]Template '!$AX$53 -> 0 | AR34: ='[25]Template '!$AZ$53 -> 0 | AS34: ='[25]Template '!$BF$53 -> 0
B35: M_085 | D35: =CONCATENATE(B35,".xlsx") -> M_085.xlsx | F35: ='[26]Template '!$C$2 -> D+M | H35: ='[26]Template '!$C$29 -> 0.44444444 | I35: ='[26]Template '!$C$30 -> n/a | J35: ='[26]Template '!$C$31 -> 0 | K35: ='[26]Template '!$C$32 -> 0.68954248 | L35: ='[26]Template '!$C$33 -> 0.6468254 | N35: ='[26]Template '!$C$74 -> 0.7 | O35: ='[26]Template '!$C$75 -> n/a | P35: ='[26]Template '!$C$76 -> 0.35714286 | Q35: ='[26]Template '!$C$77 -> 0.5922619 | R35: ='[26]Template '!$C$78 -> 0.53571429 | T35: ='[26]Template '!$C$96 -> 0.75 | U35: ='[26]Template '!$C$97 -> 0.51851852 | V35: ='[26]Template '!$C$98 -> 0 | W35: ='[26]Template '!$C$99 -> 0.45598846 | X35: ='[26]Template '!$C$100 -> 0.74761905 | Z35: ='[26]Template '!$C$52 -> 0.47222222 | AA35: ='[26]Template '!$C$53 -> 0.51851852 | AB35: ='[26]Template '!$C$54 -> 0 | AC35: ='[26]Template '!$C$55 -> 0.31018519 | AD35: ='[26]Template '!$C$56 -> 0.61269841 | AF35: ='[26]Template '!$Z$30 -> 0 | AG35: ='[26]Template '!$AB$75 -> 0 | AH35: ='[26]Template '!$AD$75 -> 0 | AI35: ='[26]Template '!$AF$75 -> 0 | AJ35: ='[26]Template '!$AR$97 -> 0 | AK35: ='[26]Template '!$AS$97 -> 1 | AL35: ='[26]Template '!$AZ$97 -> 0 | AM35: ='[26]Template '!$BB$97 -> 0 | AN35: ='[26]Template '!$AU$53 -> 1 | AO35: ='[26]Template '!$AV$53 -> 1 | AP35: ='[26]Template '!$AY$53 -> 0 | AQ35: ='[26]Template '!$AX$53 -> 0 | AR35: ='[26]Template '!$AZ$53 -> 0 | AS35: ='[26]Template '!$BF$53 -> 0
B36: M_086 | D36: =CONCATENATE(B36,".xlsx") -> M_086.xlsx | F36: =#REF! -> #REF! | H36: =#REF! -> #REF! | I36: =#REF! -> #REF! | J36: =#REF! -> #REF! | K36: =#REF! -> #REF! | L36: =#REF! -> #REF! | N36: =#REF! -> #REF! | O36: =#REF! -> #REF! | P36: =#REF! -> #REF! | Q36: =#REF! -> #REF! | R36: =#REF! -> #REF! | T36: =#REF! -> #REF! | U36: =#REF! -> #REF! | V36: =#REF! -> #REF! | W36: =#REF! -> #REF! | X36: =#REF! -> #REF! | Z36: =#REF! -> #REF! | AA36: =#REF! -> #REF! | AB36: =#REF! -> #REF! | AC36: =#REF! -> #REF! | AD36: =#REF! -> #REF! | AF36: =#REF! -> #REF! | AG36: =#REF! -> #REF! | AH36: =#REF! -> #REF! | AI36: =#REF! -> #REF! | AJ36: =#REF! -> #REF! | AK36: =#REF! -> #REF! | AL36: =#REF! -> #REF! | AM36: =#REF! -> #REF! | ... AS36: =#REF! -> #REF!
B37: M_087 | D37: =CONCATENATE(B37,".xlsx") -> M_087.xlsx | F37: =#REF! -> #REF! | H37: =#REF! -> #REF! | I37: =#REF! -> #REF! | J37: =#REF! -> #REF! | K37: =#REF! -> #REF! | L37: =#REF! -> #REF! | N37: =#REF! -> #REF! | O37: =#REF! -> #REF! | P37: =#REF! -> #REF! | Q37: =#REF! -> #REF! | R37: =#REF! -> #REF! | T37: =#REF! -> #REF! | U37: =#REF! -> #REF! | V37: =#REF! -> #REF! | W37: =#REF! -> #REF! | X37: =#REF! -> #REF! | Z37: =#REF! -> #REF! | AA37: =#REF! -> #REF! | AB37: =#REF! -> #REF! | AC37: =#REF! -> #REF! | AD37: =#REF! -> #REF! | AF37: =#REF! -> #REF! | AG37: =#REF! -> #REF! | AH37: =#REF! -> #REF! | AI37: =#REF! -> #REF! | AJ37: =#REF! -> #REF! | AK37: =#REF! -> #REF! | AL37: =#REF! -> #REF! | AM37: =#REF! -> #REF! | ... AS37: =#REF! -> #REF!
B38: M_089 | D38: =CONCATENATE(B38,".xlsx") -> M_089.xlsx | F38: ='[27]Template '!$C$2 -> D only | H38: ='[27]Template '!$C$29 -> 0.11111111 | I38: ='[27]Template '!$C$30 -> n/a | J38: ='[27]Template '!$C$31 -> 0.58333333 | K38: ='[27]Template '!$C$32 -> 0.54411765 | L38: ='[27]Template '!$C$33 -> 0.71428571 | N38: ='[27]Template '!$C$74 -> 0.24545455 | O38: ='[27]Template '!$C$75 -> n/a | P38: ='[27]Template '!$C$76 -> 0.60714286 | Q38: ='[27]Template '!$C$77 -> 0.47619048 | R38: ='[27]Template '!$C$78 -> 0.76190476 | T38: ='[27]Template '!$C$96 -> 0.8 | U38: ='[27]Template '!$C$97 -> 0.5037037 | V38: ='[27]Template '!$C$98 -> 0.5 | W38: ='[27]Template '!$C$99 -> 0.6010101 | X38: ='[27]Template '!$C$100 -> 0.89761905 | Z38: ='[27]Template '!$C$52 -> 0.40952381 | AA38: ='[27]Template '!$C$53 -> 0.5037037 | AB38: ='[27]Template '!$C$54 -> 0.5 | AC38: ='[27]Template '!$C$55 -> 0.3125 | AD38: ='[27]Template '!$C$56 -> 0.87380952 | AF38: ='[27]Template '!$Z$30 -> 0 | AG38: ='[27]Template '!$AB$75 -> 0 | AH38: ='[27]Template '!$AD$75 -> 0 | AI38: ='[27]Template '!$AF$75 -> 0 | AJ38: ='[27]Template '!$AR$97 -> 1 | AK38: ='[27]Template '!$AS$97 -> 1 | AL38: ='[27]Template '!$AZ$97 -> 1 | AM38: ='[27]Template '!$BB$97 -> 1 | AN38: ='[27]Template '!$AU$53 -> 1 | AO38: ='[27]Template '!$AV$53 -> 0 | AP38: ='[27]Template '!$AY$53 -> 0 | AQ38: ='[27]Template '!$AX$53 -> 0 | AR38: ='[27]Template '!$AZ$53 -> 0 | AS38: ='[27]Template '!$BF$53 -> 0
B39: M_090 | D39: =CONCATENATE(B39,".xlsx") -> M_090.xlsx | F39: ='[28]Template '!$C$2 -> D+M | H39: ='[28]Template '!$C$29 -> 0.38888889 | I39: ='[28]Template '!$C$30 -> n/a | J39: ='[28]Template '!$C$31 -> 0.58333333 | K39: ='[28]Template '!$C$32 -> 0.54411765 | L39: ='[28]Template '!$C$33 -> 0.54761905 | N39: ='[28]Template '!$C$74 -> 0.7 | O39: ='[28]Template '!$C$75 -> n/a | P39: ='[28]Template '!$C$76 -> 0.46428571 | Q39: ='[28]Template '!$C$77 -> 0.61904762 | R39: ='[28]Template '!$C$78 -> 0.78571429 | T39: ='[28]Template '!$C$96 -> 0.66666667 | U39: ='[28]Template '!$C$97 -> 0.24444444 | V39: ='[28]Template '!$C$98 -> 0.5 | W39: ='[28]Template '!$C$99 -> 0.5036075 | X39: ='[28]Template '!$C$100 -> 0.56666667 | Z39: ='[28]Template '!$C$52 -> 0.64444444 | AA39: ='[28]Template '!$C$53 -> 0.24444444 | AB39: ='[28]Template '!$C$54 -> 0.5 | AC39: ='[28]Template '!$C$55 -> 0.1875 | AD39: ='[28]Template '!$C$56 -> 0.70198413 | AF39: ='[28]Template '!$Z$30 -> 0 | AG39: ='[28]Template '!$AB$75 -> 0.5 | AH39: ='[28]Template '!$AD$75 -> 0.5 | AI39: ='[28]Template '!$AF$75 -> 0 | AJ39: ='[28]Template '!$AR$97 -> 1 | AK39: ='[28]Template '!$AS$97 -> 1 | AL39: ='[28]Template '!$AZ$97 -> 0 | AM39: ='[28]Template '!$BB$97 -> 0 | AN39: ='[28]Template '!$AU$53 -> 0 | AO39: ='[28]Template '!$AV$53 -> 0 | AP39: ='[28]Template '!$AY$53 -> 0 | AQ39: ='[28]Template '!$AX$53 -> 0 | AR39: ='[28]Template '!$AZ$53 -> 0 | AS39: ='[28]Template '!$BF$53 -> 0
B40: M_091 | D40: =CONCATENATE(B40,".xlsx") -> M_091.xlsx | F40: ='[29]Template '!$C$2 -> D+M | H40: ='[29]Template '!$C$29 -> 0.27777778 | I40: ='[29]Template '!$C$30 -> n/a | J40: ='[29]Template '!$C$31 -> 0.58333333 | K40: ='[29]Template '!$C$32 -> 0.54411765 | L40: ='[29]Template '!$C$33 -> 0.80952381 | N40: ='[29]Template '!$C$74 -> 0.7 | O40: ='[29]Template '!$C$75 -> n/a | P40: ='[29]Template '!$C$76 -> 0.46428571 | Q40: ='[29]Template '!$C$77 -> 0.64285714 | R40: ='[29]Template '!$C$78 -> 0.93253968 | T40: ='[29]Template '!$C$96 -> 0.75 | U40: ='[29]Template '!$C$97 -> 0.58518519 | V40: ='[29]Template '!$C$98 -> 0.5 | W40: ='[29]Template '!$C$99 -> 0.74603175 | X40: ='[29]Template '!$C$100 -> 0.98809524 | Z40: ='[29]Template '!$C$52 -> 0.7 | AA40: ='[29]Template '!$C$53 -> 0.58518519 | AB40: ='[29]Template '!$C$54 -> 0.5 | AC40: ='[29]Template '!$C$55 -> 0.45833333 | AD40: ='[29]Template '!$C$56 -> 0.90952381 | AF40: ='[29]Template '!$Z$30 -> 0 | AG40: ='[29]Template '!$AB$75 -> 0 | AH40: ='[29]Template '!$AD$75 -> 1 | AI40: ='[29]Template '!$AF$75 -> 0 | AJ40: ='[29]Template '!$AR$97 -> 1 | AK40: ='[29]Template '!$AS$97 -> 1 | AL40: ='[29]Template '!$AZ$97 -> 1 | AM40: ='[29]Template '!$BB$97 -> 1 | AN40: ='[29]Template '!$AU$53 -> 1 | AO40: ='[29]Template '!$AV$53 -> 1 | AP40: ='[29]Template '!$AY$53 -> 1 | AQ40: ='[29]Template '!$AX$53 -> 0 | AR40: ='[29]Template '!$AZ$53 -> 0 | AS40: ='[29]Template '!$BF$53 -> 0
B41: M_092 | D41: =CONCATENATE(B41,".xlsx") -> M_092.xlsx | F41: ='[30]Template '!$C$2 -> D only | H41: ='[30]Template '!$C$29 -> 0.11111111 | I41: ='[30]Template '!$C$30 -> n/a | J41: ='[30]Template '!$C$31 -> 0.58333333 | K41: ='[30]Template '!$C$32 -> 0.69117647 | L41: ='[30]Template '!$C$33 -> 0.92063492 | N41: ='[30]Template '!$C$74 -> 0.29090909 | O41: ='[30]Template '!$C$75 -> n/a | P41: ='[30]Template '!$C$76 -> 0.46428571 | Q41: ='[30]Template '!$C$77 -> 0.47619048 | R41: ='[30]Template '!$C$78 -> 0.71825397 | T41: ='[30]Template '!$C$96 -> 0.60416667 | U41: ='[30]Template '!$C$97 -> 0.20740741 | V41: ='[30]Template '!$C$98 -> 0.5 | W41: ='[30]Template '!$C$99 -> 0.55339105 | X41: ='[30]Template '!$C$100 -> 0.84126984 | Z41: ='[30]Template '!$C$52 -> 0.58333333 | AA41: ='[30]Template '!$C$53 -> 0.20740741 | AB41: ='[30]Template '!$C$54 -> 0.5 | AC41: ='[30]Template '!$C$55 -> 0.57142857 | AD41: ='[30]Template '!$C$56 -> 0.97619048 | AF41: ='[30]Template '!$Z$30 -> 1 | AG41: ='[30]Template '!$AB$75 -> 0 | AH41: ='[30]Template '!$AD$75 -> 0 | AI41: ='[30]Template '!$AF$75 -> 0 | AJ41: ='[30]Template '!$AR$97 -> 0 | AK41: ='[30]Template '!$AS$97 -> 1 | AL41: ='[30]Template '!$AZ$97 -> 1 | AM41: ='[30]Template '!$BB$97 -> 1 | AN41: ='[30]Template '!$AU$53 -> 1 | AO41: ='[30]Template '!$AV$53 -> 1 | AP41: ='[30]Template '!$AY$53 -> 0 | AQ41: ='[30]Template '!$AX$53 -> 1 | AR41: ='[30]Template '!$AZ$53 -> 0 | AS41: ='[30]Template '!$BF$53 -> 1
...

Sheet Didactic plus mSTAT
A1: Demographics | H1: IPSm | AF1: Success | BP1: Self-Efficacy
F3: Study | H3: AAE | N3: FAE | T3: LEF | Z3: UEF | AF3: AAE | AG3: FAE | AJ3: LEF | AN3: UEF | AT3: Total vasc | AU3: Total fasc | AV3: TOTAL COMBINED | BD3: Time between | BF3: Basic Training | BG3: 68W | BI3: Served as | BM3: If yes, how | BP3: Pre | CC3: Post | CO3: Procedure confidence | DC3: TRI | DD3: TRI
A4: Name | B4: Participant ID | D4: Filename | F4: Group | H4: Anatomy | I4: Pathophysiology | J4: Management | K4: Procedural | L4: Technique | N4: Anatomy | O4: Pathophysiology | P4: Management | Q4: Procedural | R4: Technique | T4: Anatomy | U4: Pathophysiology | V4: Management | W4: Procedural | X4: Technique | Z4: Anatomy | AA4: Pathophysiology | AB4: Management | AC4: Procedural | AD4: Technique | AF4: AA | AG4: CFA | AH4: SFA | AI4: PFA | AJ4: Ant | AK4: Lat | AL4: SP | AM4: DP | AN4: V | AO4: DV | AP4: BA | AQ4: MW | AR4: CT | AS4: D | AX4: Number of | BA4: Didactic | BB4: Didactic | BC4: Evaluation | BD4: didactic and | BF4: Completion | BG4: certification | BH4: Months Served | BI4: Operating Room | BJ4: If yes, how | BK4: Deployed | BL4: If yes, how | BM4: many combat | BN4: Cadaver lab | BP4: Succeed at any | BQ4: Even when things | BR4: Determine the | BS4: Control | BT4: Plan appropriate | BU4: Conduct surgical | BV4: When to use | BW4: Appropriate | BX4: ID specific | BY4: ID bony | BZ4: Performing | CA4: Caffeinated | CD4: Even when things | CE4: Determine the | CF4: Control | CG4: Plan appropriate | CH4: Conduct surgical | CI4: When to use | CJ4: Appropriate | CK4: ID specific | CL4: ID bony | CM4: Performing | DA4: File name | DF4: Success All Vascular | DG4: Success All Fasciotomy | DH4: Critical errors
AX5: Number of Evaluators | AY5: Sequence | AZ5: Sex | BA5: Iteration # | BB5: Date | BC5: Date | BD5: evaluation | BE5: Age | BF5: (month/yr) | BG5: m/yr | BH5: as a Medic | BI5: Medic or Tech | BJ5: many months | BK5: Internationally | BL5: many times | BM5: zones | BN5: experience | BP5: endeavor | BQ5: are tough | BR5: need for surgery | BS5: bleeding | BT5: interventions | BU5: procedures | BV5: tourniquet | BW5: incision | BX5: arteries | BY5: landmarks | BZ5: CPR | CA5: beverages | CC5: Succeed at any endeavor | CD5: are tough | CE5: need for surgery | CF5: bleeding | CG5: interventions | CH5: procedures | CI5: tourniquet | CJ5: incision | CK5: arteries | CL5: landmarks | CM5: CPR | CO5: Cric | CP5: AAE | CQ5: CAE | CR5: LEF | CS5: HC-WP | CT5: UEF | CU5: SM | CV5: Chest tube | CW5: HF | CX5: BAE | CY5: FAE | DC5: Adj_IPSm | DD5: IPSm
B6: M_012 | D6: =CONCATENATE(B6,".xlsx") -> M_012.xlsx | F6: ='[37]Template '!$C$2 -> D+M | H6: ='[37]Template '!$C$29 -> 0.38888889 | I6: ='[37]Template '!$C$30 -> n/a | J6: ='[37]Template '!$C$31 -> 0.83333333 | K6: ='[37]Template '!$C$32 -> 0.60294118 | L6: ='[37]Template '!$C$33 -> 0.95238095 | N6: ='[37]Template '!$C$74 -> 0.7 | O6: ='[37]Template '!$C$75 -> n/a | P6: ='[37]Template '!$C$76 -> 0.75 | Q6: ='[37]Template '!$C$77 -> 0.52380952 | R6: ='[37]Template '!$C$78 -> 0.77777778 | T6: ='[37]Template '!$C$96 -> 0.8 | U6: ='[37]Template '!$C$97 -> 0.44444444 | V6: ='[37]Template '!$C$98 -> 1 | W6: ='[37]Template '!$C$99 -> 0.43217893 | X6: ='[37]Template '!$C$100 -> 0.79404762 | Z6: ='[37]Template '!$C$52 -> 0.66944444 | AA6: ='[37]Template '!$C$53 -> 0.44444444 | AB6: ='[37]Template '!$C$54 -> 1 | AC6: ='[37]Template '!$C$55 -> 0.32291667 | AD6: ='[37]Template '!$C$56 -> 0.8734127 | AF6: ='[37]Template '!$Z$30 -> 0 | AG6: ='[37]Template '!$AB$75 -> 0 | AH6: ='[37]Template '!$AD$75 -> 0 | AI6: ='[37]Template '!$AF$75 -> 0 | AJ6: ='[37]Template '!$AR$97 -> 0 | AK6: ='[37]Template '!$AS$97 -> 0.5 | AL6: ='[37]Template '!$AZ$97 -> 0 | AM6: ='[37]Template '!$BB$97 -> 0 | AN6: ='[37]Template '!$AU$53 -> 1 | AO6: ='[37]Template '!$AV$53 -> 0.5 | AP6: ='[37]Template '!$AY$53 -> 0.5 | AQ6: ='[37]Template '!$AX$53 -> 1 | AR6: ='[37]Template '!$AZ$53 -> 0 | AS6: ='[37]Template '!$BF$53 -> 0 | AT6: =SUM(AF6,AG6,AH6,AI6) -> 0 | AU6: =SUM(AJ6:AS6) -> 3.5 | AV6: =AT6+AU6 -> 3.5 | AY6: ='[37]Template '!$E$2 -> B | AZ6: ='[37]Template '!$B$13 -> 2 | BA6: ='[37]Template '!$D$2 -> 1 | BB6: 44823 | BC6: ='[37]Template '!$F$2 -> 44988 | BD6: =DATEDIF(BB6,BC6,"d") -> 165 | BE6: ='[37]Template '!$B$12 -> 20 | BF6: ='[37]Template '!$B$14 -> 12/21 | BH6: ='[37]Template '!$B$16 -> 4 | BI6: ='[37]Template '!$B$17 -> 0 | BJ6: ='[37]Template '!$B$18 -> 0 | BK6: ='[37]Template '!$B$19 -> 0 | BL6: ='[37]Template '!$B$20 -> 0 | BM6: ='[37]Template '!$B$21 -> 0 | BN6: ='[37]Template '!$B$22 -> 0 | BP6: ='[37]Template '!$I$13 -> 4 | BQ6: ='[37]Template '!$I$14 -> 4 | BR6: ='[37]Template '!$I$15 -> 4 | BS6: ='[37]Template '!$I$16 -> 4 | BT6: ='[37]Template '!$I$17 -> 4 | BU6: ='[37]Template '!$I$18 -> 4 | BV6: ='[37]Template '!$I$19 -> 4 | BW6: ='[37]Template '!$I$20 -> 4 | BX6: ='[37]Template '!$I$21 -> 3 | BY6: ='[37]Template '!$I$23 -> 4 | BZ6: ='[37]Template '!$I$23 -> 4 | CA6: ='[37]Template '!$I$24 -> 0 | CC6: ='[37]Template '!$L$13 -> 4 | CD6: ='[37]Template '!$L$14 -> 4 | CE6: ='[37]Template '!$L$15 -> 4 | CF6: ='[37]Template '!$L$16 -> 4 | CG6: ='[37]Template '!$L$17 -> 4 | CH6: ='[37]Template '!$L$18 -> 4 | CI6: ='[37]Template '!$L$19 -> 4 | CJ6: ='[37]Template '!$L$20 -> 4 | CK6: ='[37]Template '!$L$21 -> 4 | CL6: ='[37]Template '!$L$22 -> 4 | CM6: ='[37]Template '!$L$23 -> 4 | CO6: ='[37]Template '!$O$13 -> 4 | CP6: ='[37]Template '!$O$14 -> 3 | CQ6: ='[37]Template '!$O$15 -> 3 | CR6: ='[37]Template '!$O$16 -> 4 | CS6: ='[37]Template '!$O$17 -> 4 | CT6: ='[37]Template '!$O$18 -> 3 | CU6: ='[37]Template '!$O$19 -> 2 | CV6: ='[37]Template '!$O$20 -> 3 | CW6: ='[37]Template '!$O$21 -> 4 | CX6: ='[37]Template '!$O$22 -> 3 | CY6: ='[37]Template '!$O$23 -> 4
B7: M_014 | D7: =CONCATENATE(B7,".xlsx") -> M_014.xlsx | F7: ='[2]Template '!$C$2 -> D+M | H7: ='[2]Template '!$C$29 -> 0.38888889 | I7: ='[2]Template '!$C$30 -> n/a | J7: ='[2]Template '!$C$31 -> 0.41666667 | K7: ='[2]Template '!$C$32 -> 0.66911765 | L7: ='[2]Template '!$C$33 -> 0.76984127 | N7: ='[2]Template '!$C$74 -> 0.65454545 | O7: ='[2]Template '!$C$75 -> n/a | P7: ='[2]Template '!$C$76 -> 0.39285714 | Q7: ='[2]Template '!$C$77 -> 0.4047619 | R7: ='[2]Template '!$C$78 -> 0.74603175 | T7: ='[2]Template '!$C$96 -> 0.66666667 | U7: ='[2]Template '!$C$97 -> 0.40740741 | V7: ='[2]Template '!$C$98 -> 0.5 | W7: ='[2]Template '!$C$99 -> 0.46897547 | X7: ='[2]Template '!$C$100 -> 0.68333333 | Z7: ='[2]Template '!$C$52 -> 0.78571429 | AA7: ='[2]Template '!$C$53 -> 0.40740741 | AB7: ='[2]Template '!$C$54 -> 0.5 | AC7: ='[2]Template '!$C$55 -> 0.5 | AD7: ='[2]Template '!$C$56 -> 0.7468254 | AF7: ='[2]Template '!$Z$30 -> 0 | AG7: ='[2]Template '!$AB$75 -> 0 | AH7: ='[2]Template '!$AD$75 -> 0 | AI7: ='[2]Template '!$AF$75 -> 0 | AJ7: ='[2]Template '!$AR$97 -> 0 | AK7: ='[2]Template '!$AS$97 -> 0 | AL7: ='[2]Template '!$AZ$97 -> 0 | AM7: ='[2]Template '!$BB$97 -> 1 | AN7: ='[2]Template '!$AU$53 -> 1 | AO7: ='[2]Template '!$AV$53 -> 1 | AP7: ='[2]Template '!$AY$53 -> 1 | AQ7: ='[2]Template '!$AX$53 -> 1 | AR7: ='[2]Template '!$AZ$53 -> 0 | AS7: ='[2]Template '!$BF$53 -> 0 | AT7: =SUM(AF7,AG7,AH7,AI7) -> 0 | AU7: =SUM(AJ7:AS7) -> 5 | AV7: =AT7+AU7 -> 5 | AY7: ='[2]Template '!$E$2 -> B | AZ7: ='[2]Template '!$B$13 -> 1 | BA7: ='[2]Template '!$D$2 -> 1 | BB7: 44823 | BC7: ='[2]Template '!$F$2 -> 44992 | BD7: =DATEDIF(BB7,BC7,"d") -> 169 | BE7: ='[2]Template '!$B$12 -> 23 | BF7: ='[2]Template '!$B$14 -> 11/20 | BH7: ='[2]Template '!$B$16 -> 18 | BI7: ='[2]Template '!$B$17 -> 0 | BJ7: ='[2]Template '!$B$18 -> 0 | BK7: ='[2]Template '!$B$19 -> 1 | BL7: ='[2]Template '!$B$20 -> 1 | BM7: ='[2]Template '!$B$21 -> 1 | BN7: ='[2]Template '!$B$22 -> 0 | BP7: ='[2]Template '!$I$13 -> 4 | BQ7: ='[2]Template '!$I$14 -> 4 | BR7: ='[2]Template '!$I$15 -> 4 | BS7: ='[2]Template '!$I$16 -> 4 | BT7: ='[2]Template '!$I$17 -> 4 | BU7: ='[2]Template '!$I$18 -> 3 | BV7: ='[2]Template '!$I$19 -> 5 | BW7: ='[2]Template '!$I$20 -> 3 | BX7: ='[2]Template '!$I$21 -> 3 | BY7: ='[2]Template '!$I$23 -> 4 | BZ7: ='[2]Template '!$I$23 -> 4 | CA7: ='[2]Template '!$I$24 -> 2 | CC7: ='[2]Template '!$L$13 -> 4 | CD7: ='[2]Template '!$L$14 -> 4 | CE7: ='[2]Template '!$L$15 -> 4 | CF7: ='[2]Template '!$L$16 -> 4 | CG7: ='[2]Template '!$L$17 -> 4 | CH7: ='[2]Template '!$L$18 -> 3 | CI7: ='[2]Template '!$L$19 -> 5 | CJ7: ='[2]Template '!$L$20 -> 4 | CK7: ='[2]Template '!$L$21 -> 3 | CL7: ='[2]Template '!$L$22 -> 4 | CM7: ='[2]Template '!$L$23 -> 4 | CO7: ='[2]Template '!$O$13 -> 3 | CP7: ='[2]Template '!$O$14 -> 3 | CQ7: ='[2]Template '!$O$15 -> 2 | CR7: ='[2]Template '!$O$16 -> 4 | CS7: ='[2]Template '!$O$17 -> 5 | CT7: ='[2]Template '!$O$18 -> 3 | CU7: ='[2]Template '!$O$19 -> 1 | CV7: ='[2]Template '!$O$20 -> 1 | CW7: ='[2]Template '!$O$21 -> 2 | CX7: ='[2]Template '!$O$22 -> 3 | CY7: ='[2]Template '!$O$23 -> 3
